Workbook

Sheet ABOUT

Sheet Summary
A1: =settings!B1&" "&"Proposal" -> Bartells, Adam Proposal
A2: 45778
A4: Item | B4: *Annual Est Fee | C4: As MO Billing | D4: As Qtr Billing | E4: Notes
A5: Total Annual Estimate | B5: =Detail!O11 -> 7556.25 | C5: =$B$5/12 -> 629.6875 | D5: =$B$5/4 -> 1889.0625 | E5: Click HERE for detail
A6: *The figures shown here are based on the average annual fee, see detail tab for the est hours per period and high/low projection.
A7: Discount: | B7: 0
B8: =B5-(B5*B7) -> 7556.25 | C8: =$B$8/12 -> 629.6875 | D8: =$B$8/4 -> 1889.0625
A11: Summary By Service
A12: Name | B12: Annual Estimate
A13: IncomeTax | B13: =SUMIF(Detail!Q:Q,Summary!A13,Detail!O:O) -> 2156.25
A14: Accounting | B14: =SUMIF(Detail!Q:Q,Summary!A14,Detail!O:O) -> 2700
A15: Advisory | B15: =SUMIF(Detail!Q:Q,Summary!A15,Detail!O:O) -> 2700
B16: =SUM(B13:B15) -> 7556.25
A27: Summay By Entity
A28: Name | B28: Annual Estimate
A29: AMNA Enterprises, LLC | B29: =SUMIF(Detail!A:A,Summary!A29,Detail!O:O) -> 6681.25
A30: Bartells, Adam & Mindy | B30: =SUMIF(Detail!A:A,Summary!A30,Detail!O:O) -> 875
B31: =SUM(B29:B30) -> 7556.25
K58: Gross Sales | L58: 17165
K59: Nominee to 87-4556114 | L59: -17165 | M59: Other Expenses
L60: =SUM(L58:L59) -> 0
J135: 14000
J136: =+J135*0.18 -> 2520
A165: Recommendations/My Plan
A166: - Cash Flow Optimization | B166: Push estiamtes to YE
A167: - Tax efficiency | B167: Move to S corp, go forward it will impact as you grow, move expenses into businesses in an "intelligent way"
A168: - Risk Mitigation | B168: Intelligent aggression

Sheet 1065
A5: Payroll / Wages
A30: Taxes and licenses?
S35: Investigate
A37: Retirement or other EE Benefits?
A45: Passive vs Active
Z60: =44668.83-5640 -> 39028.83
A70: other expense

Sheet Detail
A1: =Summary!A1 -> Bartells, Adam Proposal
A2: =Summary!A2 -> 45778
C3: =VLOOKUP(C4,settings!$E:$F,2,FALSE) -> 12 | E3: =VLOOKUP(E4,settings!$E:$F,2,FALSE) -> 4 | G3: =VLOOKUP(G4,settings!$E:$F,2,FALSE) -> 1
C4: Monthly | E4: Quarterly | G4: Annually | J4: Yearly Totals/Estimates
A5: Entity | B5: Service | C5: LOW | D5: HIGH | E5: LOW | F5: HIGH | G5: LOW | H5: HIGH | J5: LOW | K5: HIGH | L5: Avg | M5: LOW | N5: HIGH | O5: Avg | P5: Notes | Q5: Service | R5: Jurisdiction
A6: =settings!B2 -> AMNA Enterprises, LLC | B6: TaxPrep - 1065 | G6: 3 | H6: =ROUNDUP(G6*settings!$O$2,0) -> 4 | J6: =G6*$G$3 -> 3 | K6: =H6*$G$3 -> 4 | L6: =AVERAGE(J6,K6) -> 3.5 | M6: =settings!$K$13*G6 -> 750 | N6: =settings!$K$13*H6 -> 1000 | O6: =AVERAGE(M6,N6) -> 875 | P6: Owned by trust, non-passive O&G | Q6: IncomeTax | R6: Fed
A7: =A6 -> AMNA Enterprises, LLC | B7: TaxPrep - TX | G7: 1.25 | H7: =ROUNDUP(G7*settings!$O$2,0) -> 2 | J7: =G7*$G$3 -> 1.25 | K7: =H7*$G$3 -> 2 | L7: =AVERAGE(J7,K7) -> 1.625 | M7: =settings!$K$13*G7 -> 312.5 | N7: =settings!$K$13*H7 -> 500 | O7: =AVERAGE(M7,N7) -> 406.25 | P7: Depending on income threshold | Q7: IncomeTax | R7: State
A8: Bartells, Adam & Mindy | B8: TaxPrep - 1040 | G8: 3 | H8: =ROUNDUP(G8*settings!$O$2,0) -> 4 | J8: =G8*$G$3 -> 3 | K8: =H8*$G$3 -> 4 | L8: =AVERAGE(J8,K8) -> 3.5 | M8: =settings!$K$13*G8 -> 750 | N8: =settings!$K$13*H8 -> 1000 | O8: =AVERAGE(M8,N8) -> 875 | P8: Schedule C and K1s | Q8: IncomeTax | R8: Fed
A9: =A7 -> AMNA Enterprises, LLC | B9: Accounting | C9: 1 | D9: =ROUNDUP(C9*settings!$O$2,0) -> 2 | J9: =C9*$C$3 -> 12 | K9: =D9*$C$3 -> 24 | L9: =AVERAGE(J9,K9) -> 18 | M9: =(settings!$K$9*C9)*$C$3 -> 1800 | N9: =(settings!$K$9*D9)*$C$3 -> 3600 | O9: =AVERAGE(M9,N9) -> 2700 | P9: Estimate based on emails/conversation with Adam, will update / change as things progress and internal procedures are developed/handed off. | Q9: Accounting
A10: =A7 -> AMNA Enterprises, LLC | B10: Review | C10: 1 | D10: =ROUNDUP(C10*settings!$O$2,0) -> 2 | J10: =C10*$C$3 -> 12 | K10: =D10*$C$3 -> 24 | L10: =AVERAGE(J10,K10) -> 18 | M10: =(settings!$K$9*C10)*$C$3 -> 1800 | N10: =(settings!$K$9*D10)*$C$3 -> 3600 | O10: =AVERAGE(M10,N10) -> 2700 | Q10: Advisory
B11: Total Hrs/Period | C11: =SUM(C6:C10) -> 2 | D11: =SUM(D6:D10) -> 4 | E11: =SUM(E6:E10) -> 0 | F11: =SUM(F6:F10) -> 0 | G11: =SUM(G6:G10) -> 7.25 | H11: =SUM(H6:H10) -> 10 | J11: =SUM(J6:J10) -> 31.25 | K11: =SUM(K6:K10) -> 58 | L11: =SUM(L6:L10) -> 44.625 | M11: =SUM(M6:M10) -> 5412.5 | N11: =SUM(N6:N10) -> 9700 | O11: =SUM(O6:O10) -> 7556.25
A13: *Estimate for item is based on firms required minimum fee

Sheet OldFormat
A1: TBD | J1: BK | K1: 1 | L1: 65 | M1: Internal items/notes
J2: BK | K2: 2 | L2: 165
A3: Admin Items | J3: BK | K3: 3 | L3: 121
A4: Client Info | C4: Business Organized As | F4: Accounting System Setup | J4: CPA2 | K4: 1 | L4: 135
A5: TBD | C5: TBD | F5: (our system, client system, QB's online or other?) | J5: CPA1 | K5: 2 | L5: 121
F6: TBD | J6: CPA2 | K6: 3 | L6: 135
A7: Services Provided
A8: Services & Details | B8: Yes/No/Other | C8: Notes/Details | F8: Examples: | G8: L:\FORMS & LETTERS & ADMIN\2023 Engagement Letters
A9: ACCT & BKKEEPING | B9: Yes | C9: TBD | G9: Watts Drilling Company, LP 2023
A10: MNTHLY/QTRL PACKET | B10: Yes | C10: TBD | G10: Tri-Media Publications 2023
A11: PAYROLL | B11: No | C11: N/A
A12: INCOME TAX | B12: Yes | C12: TBD
A13: SALES TAX | B13: TBD | C13: TBD
A14: TX PROPERTY TAX | B14: No | C14: N/A
A15: MISC/OTHER | B15: No | C15: N/A
A16: TBD
A19: Time & Cost Summary for Client - Recurring Monthly Service
A20: By Task | B20: Mo | C20: Qtrly | D20: Annual | E20: TOTAL MO | F20: TOTAL QTR | G20: TOTAL ANN | H20: Grand Total | O20: MO | P20: QTR | Q20: Annual
A21: ACCT & BKKEEPING | B21: =SUMIF($B$46:$B$57,A21,$G$46:$G$57) -> 1120 | C21: =SUMIF($B$59:$B$65,A21,$G$59:$G$65) -> 0 | D21: =SUMIF($B$67:$B$77,A21,$G$67:$G$77) -> 0 | E21: =+B21*O21 -> 13440 | F21: =+C21*P21 -> 0 | G21: =+D21*Q21 -> 0 | H21: =SUM(E21:G21) -> 13440 | O21: 12 | P21: 4 | Q21: 1
A22: MNTHLY/QTRL PACKET | B22: =SUMIF($B$46:$B$57,A22,$G$46:$G$57) -> 0 | C22: =SUMIF($B$59:$B$65,A22,$G$59:$G$65) -> 218.5 | D22: =SUMIF($B$67:$B$77,A22,$G$67:$G$77) -> 0 | E22: =+B22*O22 -> 0 | F22: =+C22*P22 -> 874 | G22: =+D22*Q22 -> 0 | H22: =SUM(E22:G22) -> 874 | O22: 12 | P22: 4 | Q22: 1
A23: PAYROLL | B23: =SUMIF($B$46:$B$57,A23,$G$46:$G$57) -> 247.5 | C23: =SUMIF($B$59:$B$65,A23,$G$59:$G$65) -> 0 | D23: =SUMIF($B$67:$B$77,A23,$G$67:$G$77) -> 0 | E23: =+B23*O23 -> 2970 | F23: =+C23*P23 -> 0 | G23: =+D23*Q23 -> 0 | H23: =SUM(E23:G23) -> 2970 | O23: 12 | P23: 4 | Q23: 1
A24: INCOME TAX | B24: =SUMIF($B$46:$B$57,A24,$G$46:$G$57) -> 0 | C24: =SUMIF($B$59:$B$65,A24,$G$59:$G$65) -> 363 | D24: =SUMIF($B$67:$B$77,A24,$G$67:$G$77) -> 1266 | E24: =+B24*O24 -> 0 | F24: =+C24*P24 -> 1452 | G24: =+D24*Q24 -> 1266 | H24: =SUM(E24:G24) -> 2718 | O24: 12 | P24: 4 | Q24: 1
A25: SALES TAX | B25: =SUMIF($B$46:$B$57,A25,$G$46:$G$57) -> 495 | C25: =SUMIF($B$59:$B$65,A25,$G$59:$G$65) -> 0 | D25: =SUMIF($B$67:$B$77,A25,$G$67:$G$77) -> 0 | E25: =+B25*O25 -> 5940 | F25: =+C25*P25 -> 0 | G25: =+D25*Q25 -> 0 | H25: =SUM(E25:G25) -> 5940 | O25: 12 | P25: 4 | Q25: 1
A26: TX PROPERTY TAX | B26: =SUMIF($B$46:$B$57,A26,$G$46:$G$57) -> 0 | C26: =SUMIF($B$59:$B$65,A26,$G$59:$G$65) -> 0 | D26: =SUMIF($B$67:$B$77,A26,$G$67:$G$77) -> 0 | E26: =+B26*O26 -> 0 | F26: =+C26*P26 -> 0 | G26: =+D26*Q26 -> 0 | H26: =SUM(E26:G26) -> 0 | O26: 12 | P26: 4 | Q26: 1
A27: MISC/OTHER | B27: =SUMIF($B$46:$B$57,A27,$G$46:$G$57) -> 0 | C27: =SUMIF($B$59:$B$65,A27,$G$59:$G$65) -> 0 | D27: =SUMIF($B$67:$B$77,A27,$G$67:$G$77) -> 0 | E27: =+B27*O27 -> 0 | F27: =+C27*P27 -> 0 | G27: =+D27*Q27 -> 0 | H27: =SUM(E27:G27) -> 0 | O27: 12 | P27: 4 | Q27: 1
A28: Consulting/Planning | B28: =SUMIF($B$46:$B$57,A28,$G$46:$G$57) -> 0 | C28: =SUMIF($B$59:$B$65,A28,$G$59:$G$65) -> 0 | D28: =SUMIF($B$67:$B$77,A28,$G$67:$G$77) -> 0 | E28: =+B28*O28 -> 0 | F28: =+C28*P28 -> 0 | G28: =20*150 -> 3000 | H28: =SUM(E28:G28) -> 3000 | I28: 20 hrs of consulting/planning built in
A29: Cost | E29: =SUM(E21:E27) -> 22350 | F29: =SUM(F21:F27) -> 2326 | G29: =SUM(G21:G28) -> 4266 | H29: =SUM(H21:H28) -> 28942 | I29: Total Annual Internal Cost
H30: =+H29/12 -> 2411.8333 | I30: Cost/MO
H31: =(-150*20)/12 -> -250 | I31: Built in consluting/planning
A32: By Individual | B32: Mo | C32: Qtrly | D32: Annual | E32: Total | H32: =+M32*-0.05 -> -0.15 | I32: Monthly client discount, # srvs x 5% | M32: 3 | N32: # services used
A33: BK | B33: =SUMIF($C$46:$C$79,A33,$D$46:$D$79) -> 10.5 | C33: =SUMIF($C$46:$C$79,A33,$E$46:$E$79) -> 0 | D33: =SUMIF($C$46:$C$79,A33,$F$46:$F$79) -> 0 | E33: =SUM(B33:D33) -> 10.5 | H33: =(H30+H31)*(1+H32) -> 1837.5583 | I33: Minimum Req Monthly Fee
A34: CPA1 | B34: =SUMIF($C$46:$C$79,A34,$D$46:$D$79) -> 0 | C34: =SUMIF($C$46:$C$79,A34,$E$46:$E$79) -> 4 | D34: =SUMIF($C$46:$C$79,A34,$F$46:$F$79) -> 6 | E34: =SUM(B34:D34) -> 10
A35: CPA2 | B35: =SUMIF($C$46:$C$79,A35,$D$46:$D$79) -> 0 | C35: =SUMIF($C$46:$C$79,A35,$E$46:$E$79) -> 0 | D35: =SUMIF($C$46:$C$79,A35,$F$46:$F$79) -> 4 | E35: =SUM(B35:D35) -> 4
A36: Total Time by Category | B36: =SUM(B33:B35) -> 10.5 | C36: =SUM(C33:C35) -> 4 | D36: =SUM(D33:D35) -> 10 | E36: =SUM(E33:E35) -> 24.5
A37: Annualized | B37: 12 | C37: 4 | D37: 1
A38: BK | B38: =+B33*B37 -> 126 | C38: =+C33*C37 -> 0 | D38: =+D33*D37 -> 0 | E38: =SUM(B38:D38) -> 126
A39: CPA1 | B39: =+B34*B37 -> 0 | C39: =+C34*C37 -> 16 | D39: =+D34*D37 -> 6 | E39: =SUM(B39:D39) -> 22
A40: CPA2 | B40: =+B35*B37 -> 0 | C40: =+C35*C37 -> 0 | D40: =+D35*D37 -> 4 | E40: =SUM(B40:D40) -> 4
A41: Total Time Annually | B41: =+B36*B37 -> 126 | C41: =+C36*C37 -> 16 | D41: =+D36*D37 -> 10 | E41: =SUM(B41:D41) -> 152
B44: Time and Cost Budget Details | M44: Practice CS Projects/Task
...

Sheet setup

Sheet settings
A1: Primary Contact | B1: Bartells, Adam | E1: Reccurance | H1: Staff/Rates Range | M1: Symbols/Ref | O1: Est High From Low %
A2: Primary Client | B2: AMNA Enterprises, LLC | E2: Monthly | F2: 12 | H2: Blended/Avg | M2: - | O2: 1.25
E3: Quarterly | F3: 4 | H3: Function | I3: Low | J3: High
E4: Annually | F4: 1 | H4: Bk | I4: 150 | J4: 180
H5: CPA | I5: 250 | J5: 250
H7: Detail
H8: Ref | I8: Function | J8: Lvl | K8: Rate
H9: =I9&$M$2&J9 -> w6w3-1 | I9: w6w3 | J9: 1 | K9: =I4 -> 150
H10: =I10&$M$2&J10 -> BK-2 | I10: BK | J10: 2 | K10: =AVERAGE(K9,K11) -> 165
H11: =I11&$M$2&J11 -> BK-3 | I11: BK | J11: 3 | K11: =J4 -> 180
H12: =I12&$M$2&J12 -> CPA-1 | I12: CPA | J12: 1 | K12: =I5 -> 250
H13: =I13&$M$2&J13 -> CPA-2 | I13: CPA | J13: 2 | K13: =AVERAGE(K12,K14) -> 250
H14: =I14&$M$2&J14 -> CPA-3 | I14: CPA | J14: 3 | K14: =J5 -> 250
