Workbook

Sheet MO Client SOW & Est
A1: BUSINESS NAME | L1: Internal items/notes (DO NOT PRINT OR SHOW) | Q1: Formula
A2: Date: | B2: Prepared By: | L2: Last Updated: | M2: KC - 7/14/18
L3: SOW TYPE: | M3: MONTHLY CLIENT
A4: Admin Items | L4: =COUNTIF(B10:B16,"Yes") -> 3 | M4: # services used (Determines Discount)
A5: Client Info | C5: Business Organized As | F5: Accounting System Setup (If Present)
A6: Individual's Name | C6: TBD | F6: (our system, client system, QB's online or other?)
F7: TBD | L7: General Hourly Bill & Cost Rates
A8: Services Provided | L8: Code | M8: Rate | N8: Description | O8: Internal Position Title | P8: Internal Cost Rate
A9: Services & Details | B9: Yes/No/Other | C9: Notes/Details | L9: Admin | M9: 40 | N9: Admin | O9: Admin | P9: 16
A10: ACCT & BKKEEPING | B10: Yes | C10: TBD | L10: BK | M10: 45 | N10: Bookkeeper | O10: Bookkeeper | P10: 18
A11: MNTHLY/QTRL PACKET | B11: Yes | C11: TBD | L11: BK2 | M11: 65 | N11: Accountant | O11: Accountant | P11: 20
A12: PAYROLL | B12: No | C12: N/A | L12: Acct | M12: 70 | N12: Accounting Ptr | O12: Accounting Ptr | P12: 0 | Q12: N/A - Captured in Admin
A13: INCOME TAX | B13: Yes | C13: TBD | L13: CPA1 | M13: 121 | N13: Tax Preparer | O13: Tax Preparer | P13: 25
A14: SALES TAX | B14: No | C14: N/A | L14: CPA2 | M14: 135 | N14: Tax Reviewer | O14: Tax Reviewer | P14: 30
A15: TX PROPERTY TAX | B15: No | C15: N/A | L15: CPA3 | M15: 150 | N15: Tax Partner | O15: Tax Partner | P15: 0 | Q15: N/A - Captured in Admin
A16: MISC/OTHER | B16: No | C16: N/A
A17: TBD
L18: Realized Hourly Rate (After Discount)
A19: Time & Cost Summary for Client - Recurring Monthly Service | L19: Code | M19: Total Hrs | N19: % of Total Hrs | O19: Raw Fee | P19: % of Fee | Q19: Net Fee | R19: Act Hrly Rate | S19: Dept
A20: By Task | B20: Mo | C20: Qtrly | D20: Annual | E20: TOTAL MO | F20: TOTAL QTR | G20: TOTAL ANN | H20: Grand Total | L20: Admin | M20: =(SUMIF($B$47:$B$76,L20,$C$47:$C$76)*12)+(SUMIF($B$47:$B$76,L20,$D$47:$D$76)*4)+SUMIF($B$47:$B$76,L20,$E$47:$E$76) -> 0 | N20: =+M20/$M$27 -> 0 | O20: =+M20*M9 -> 0 | P20: =+O20/$O$27 -> 0 | Q20: =(+$H$34*12)*P20 -> 0 | R20: =IF(M20>0,+Q20/M20,0) -> 0 | S20: Admin
A21: ACCT & BKKEEPING | B21: =SUMIF($A$47:$A$55,A21,$F$47:$F$55) -> 446 | C21: =SUMIF($A$57:$A$64,A21,$F$57:$F$64) -> 121 | D21: =SUMIF($A$66:$A$76,A21,$F$66:$F$76) -> 242 | E21: =+B21*12 -> 5352 | F21: =+C21*4 -> 484 | G21: =+D21*1 -> 242 | H21: =SUM(E21:G21) -> 6078 | L21: BK | M21: =(SUMIF($B$47:$B$76,L21,$C$47:$C$76)*12)+(SUMIF($B$47:$B$76,L21,$D$47:$D$76)*4)+SUMIF($B$47:$B$76,L21,$E$47:$E$76) -> 0 | N21: =+M21/$M$27 -> 0 | O21: =+M21*M10 -> 0 | P21: =+O21/$O$27 -> 0 | Q21: =(+$H$34*12)*P21 -> 0 | R21: =IF(M21>0,+Q21/M21,0) -> 0 | S21: Acct
A22: MNTHLY/QTRL PACKET | B22: =SUMIF($A$47:$A$55,A22,$F$47:$F$55) -> 0 | C22: =SUMIF($A$57:$A$64,A22,$F$57:$F$64) -> 65 | D22: =SUMIF($A$66:$A$76,A22,$F$66:$F$76) -> 0 | E22: =+B22*12 -> 0 | F22: =+C22*4 -> 260 | G22: =+D22*1 -> 0 | H22: =SUM(E22:G22) -> 260 | L22: BK2 | M22: =(SUMIF($B$47:$B$76,L22,$C$47:$C$76)*12)+(SUMIF($B$47:$B$76,L22,$D$47:$D$76)*4)+SUMIF($B$47:$B$76,L22,$E$47:$E$76) -> 89 | N22: =+M22/$M$27 -> 0.73251029 | O22: =+M22*M11 -> 5785 | P22: =+O22/$O$27 -> 0.59021578 | Q22: =(+$H$34*12)*P22 -> 5134.8773 | R22: =IF(M22>0,+Q22/M22,0) -> 57.695251 | S22: Acct
A23: PAYROLL | B23: =SUMIF($A$47:$A$55,A23,$F$47:$F$55) -> 65 | C23: =SUMIF($A$57:$A$64,A23,$F$57:$F$64) -> 130 | D23: =SUMIF($A$66:$A$76,A23,$F$66:$F$76) -> 325 | E23: =+B23*12 -> 780 | F23: =+C23*4 -> 520 | G23: =+D23*1 -> 325 | H23: =SUM(E23:G23) -> 1625 | L23: Acct | M23: =(SUMIF($B$47:$B$76,L23,$C$47:$C$76)*12)+(SUMIF($B$47:$B$76,L23,$D$47:$D$76)*4)+SUMIF($B$47:$B$76,L23,$E$47:$E$76) -> 0 | N23: =+M23/$M$27 -> 0 | O23: =+M23*M12 -> 0 | P23: =+O23/$O$27 -> 0 | Q23: =(+$H$34*12)*P23 -> 0 | R23: =IF(M23>0,+Q23/M23,0) -> 0 | S23: Acct
A24: INCOME TAX | B24: =SUMIF($A$47:$A$55,A24,$F$47:$F$55) -> 0 | C24: =SUMIF($A$57:$A$64,A24,$F$57:$F$64) -> 121 | D24: =SUMIF($A$66:$A$76,A24,$F$66:$F$76) -> 1354.5 | E24: =+B24*12 -> 0 | F24: =+C24*4 -> 484 | G24: =+D24*1 -> 1354.5 | H24: =SUM(E24:G24) -> 1838.5 | L24: CPA1 | M24: =(SUMIF($B$47:$B$76,L24,$C$47:$C$76)*12)+(SUMIF($B$47:$B$76,L24,$D$47:$D$76)*4)+SUMIF($B$47:$B$76,L24,$E$47:$E$76) -> 26.5 | N24: =+M24/$M$27 -> 0.218107 | O24: =+M24*M13 -> 3206.5 | P24: =+O24/$O$27 -> 0.3271438 | Q24: =(+$H$34*12)*P24 -> 2846.1511 | R24: =IF(M24>0,+Q24/M24,0) -> 107.40193 | S24: Tax
A25: SALES TAX | B25: =SUMIF($A$47:$A$55,A25,$F$47:$F$55) -> 0 | C25: =SUMIF($A$57:$A$64,A25,$F$57:$F$64) -> 0 | D25: =SUMIF($A$66:$A$76,A25,$F$66:$F$76) -> 0 | E25: =+B25*12 -> 0 | F25: =+C25*4 -> 0 | G25: =+D25*1 -> 0 | H25: =SUM(E25:G25) -> 0 | L25: CPA2 | M25: =(SUMIF($B$47:$B$76,L25,$C$47:$C$76)*12)+(SUMIF($B$47:$B$76,L25,$D$47:$D$76)*4)+SUMIF($B$47:$B$76,L25,$E$47:$E$76) -> 6 | N25: =+M25/$M$27 -> 0.049382716 | O25: =+M25*M14 -> 810 | P25: =+O25/$O$27 -> 0.082640412 | Q25: =(+$H$34*12)*P25 -> 718.97159 | R25: =IF(M25>0,+Q25/M25,0) -> 119.8286 | S25: Tax
A26: TX PROPERTY TAX | B26: =SUMIF($A$47:$A$55,A26,$F$47:$F$55) -> 0 | C26: =SUMIF($A$57:$A$64,A26,$F$57:$F$64) -> 0 | D26: =SUMIF($A$66:$A$76,A26,$F$66:$F$76) -> 0 | E26: =+B26*12 -> 0 | F26: =+C26*4 -> 0 | G26: =+D26*1 -> 0 | H26: =SUM(E26:G26) -> 0 | L26: CPA3 | M26: =(SUMIF($B$47:$B$76,L26,$C$47:$C$76)*12)+(SUMIF($B$47:$B$76,L26,$D$47:$D$76)*4)+SUMIF($B$47:$B$76,L26,$E$47:$E$76) -> 0 | N26: =+M26/$M$27 -> 0 | O26: =+M26*M15 -> 0 | P26: =+O26/$O$27 -> 0 | Q26: =(+$H$34*12)*P26 -> 0 | R26: =IF(M26>0,+Q26/M26,0) -> 0 | S26: Tax
A27: MISC/OTHER | B27: =SUMIF($A$47:$A$55,A27,$F$47:$F$55) -> 0 | C27: =SUMIF($A$57:$A$64,A27,$F$57:$F$64) -> 0 | D27: =SUMIF($A$66:$A$76,A27,$F$66:$F$76) -> 0 | E27: =+B27*12 -> 0 | F27: =+C27*4 -> 0 | G27: =+D27*1 -> 0 | H27: =SUM(E27:G27) -> 0 | L27: Total Hrs/Yr | M27: =SUM(M20:M26) -> 121.5 | N27: =SUM(N20:N26) -> 1 | O27: =SUM(O20:O26) -> 9801.5 | P27: =SUM(P20:P26) -> 1 | Q27: =SUM(Q20:Q26) -> 8700
A28: Consulting/Planning | B28: =SUMIF($A$47:$A$55,A28,$F$47:$F$55) -> 0 | C28: =SUMIF($A$57:$A$64,A28,$F$57:$F$64) -> 0 | D28: =SUMIF($A$66:$A$76,A28,$F$66:$F$76) -> 0 | E28: =+B28*N27 -> 0 | F28: =+C28*O27 -> 0 | G28: =10*150 -> 1500 | H28: =SUM(E28:G28) -> 1500 | I28: 8 hrs of consulting/planning built in
A29: Cost | E29: =SUM(E21:E27) -> 6132 | F29: =SUM(F21:F27) -> 1748 | G29: =SUM(G21:G28) -> 3421.5 | H29: =SUM(H21:H28) -> 11301.5 | I29: Total Annual Internal Cost
H30: =+H29/12 -> 941.79167 | I30: Initial Cost/MO | L30: Profitability & Gross/Net Profit %
H31: =(-150*8)/12 -> -100 | I31: Built in consluting/planning | L31: Code | M31: Net Fee | N31: Tota Ann Cost | O31: Profitability | P31: Gross Profit % | Q31: Est G&A Exp % | R31: Take Home % | S31: Dept
A32: By Individual | B32: Mo | C32: Qtrly | D32: Annual | E32: Total | H32: =+L4*-0.05 -> -0.15 | I32: Monthly client discount, # srvs x 5% | L32: Admin | M32: =+Q20 -> 0 | N32: =+M20*P9 -> 0 | O32: =+M32-N32 -> 0 | P32: =IF(O32>0,O32/M32,"-") -> - | Q32: 0.38 | R32: =IF(O32>0,P32-Q32,"-") -> - | S32: Admin
A33: Admin | B33: =SUMIF($B$47:$B$77,"Admin",$C$47:$C$77) -> 0 | C33: =SUMIF($B$47:$B$77,"Admin",$D$47:$D$77) -> 0 | D33: =SUMIF($B$47:$B$77,"Admin",$E$47:$E$77) -> 0 | E33: =SUM(B33:D33) -> 0 | H33: =(H30+H31)*(1+H32) -> 715.52292 | I33: Est Monthly Fee | L33: BK | M33: =+Q21 -> 0 | N33: =+M21*P10 -> 0 | O33: =+M33-N33 -> 0 | P33: =IF(O33>0,O33/M33,"-") -> - | Q33: 0.38 | R33: =IF(O33>0,P33-Q33,"-") -> - | S33: Acct
A34: BK/BK2/Acct | B34: =SUMIF($B$47:$B$77,"BK2",$C$47:$C$77)+SUMIF($B$47:$B$77,"BK",$C$47:$C$77)+SUMIF($B$47:$B$77,"Acct",$C$47:$C$77) -> 6 | C34: =SUMIF($B$47:$B$77,"BK2",$D$47:$D$77)+SUMIF($B$47:$B$77,"BK",$D$47:$D$77)+SUMIF($B$47:$B$77,"Acct",$D$47:$D$77) -> 3 | D34: =SUMIF($B$47:$B$77,"BK2",$E$47:$E$77)+SUMIF($B$47:$B$77,"BK",$E$47:$E$77)+SUMIF($B$47:$B$77,"Acct",$E$47:$E$77) -> 5 | E34: =SUM(B34:D34) -> 14 | H34: 725 | I34: MO FEE (Rounded) | L34: BK2 | M34: =+Q22 -> 5134.8773 | N34: =+M22*P11 -> 1780 | O34: =+M34-N34 -> 3354.8773 | P34: =IF(O34>0,O34/M34,"-") -> 0.65335102 | Q34: 0.38 | R34: =IF(O34>0,P34-Q34,"-") -> 0.27335102 | S34: Acct
A35: CPA 1/2/3 | B35: =SUMIF($B$47:$B$77,"CPA1",$C$47:$C$77)+SUMIF($B$47:$B$77,"CPA2",$C$47:$C$77)+SUMIF($B$47:$B$77,"CPA3",$C$47:$C$77) -> 1 | C35: =SUMIF($B$47:$B$77,"CPA1",$D$47:$D$77)+SUMIF($B$47:$B$77,"CPA2",$D$47:$D$77)+SUMIF($B$47:$B$77,"CPA3",$D$47:$D$77) -> 2 | D35: =SUMIF($B$47:$B$77,"CPA1",$E$47:$E$77)+SUMIF($B$47:$B$77,"CPA2",$E$47:$E$77)+SUMIF($B$47:$B$77,"CPA3",$E$47:$E$77) -> 12.5 | E35: =SUM(B35:D35) -> 15.5 | L35: Acct | M35: =+Q23 -> 0 | N35: =+M23*P12 -> 0 | O35: =+M35-N35 -> 0 | P35: =IF(O35>0,O35/M35,"-") -> - | Q35: 0.38 | R35: =IF(O35>0,P35-Q35,"-") -> - | S35: Acct
A36: Total by Category | B36: =SUM(B33:B35) -> 7 | C36: =SUM(C33:C35) -> 5 | D36: =SUM(D33:D35) -> 17.5 | E36: =SUM(E33:E35) -> 29.5 | L36: CPA1 | M36: =+Q24 -> 2846.1511 | N36: =+M24*P13 -> 662.5 | O36: =+M36-N36 -> 2183.6511 | P36: =IF(O36>0,O36/M36,"-") -> 0.76722951 | Q36: 0.38 | R36: =IF(O36>0,P36-Q36,"-") -> 0.38722951 | S36: Tax
A37: Annualized | B37: 12 | C37: 4 | D37: 1 | L37: CPA2 | M37: =+Q25 -> 718.97159 | N37: =+M25*P14 -> 180 | O37: =+M37-N37 -> 538.97159 | P37: =IF(O37>0,O37/M37,"-") -> 0.7496424 | Q37: 0.38 | R37: =IF(O37>0,P37-Q37,"-") -> 0.3696424 | S37: Tax
A38: Admin | B38: =+B33*B37 -> 0 | C38: =+C33*C37 -> 0 | D38: =+D33*D37 -> 0 | E38: =SUM(B38:D38) -> 0 | L38: CPA3 | M38: =+Q26 -> 0 | N38: =+M26*P15 -> 0 | O38: =+M38-N38 -> 0 | P38: =IF(O38>0,O38/M38,"-") -> - | Q38: 0.38 | R38: =IF(O38>0,P38-Q38,"-") -> - | S38: Tax
A39: BK/BK2/Acct | B39: =+B34*B37 -> 72 | C39: =+C34*C37 -> 12 | D39: =+D34*D37 -> 5 | E39: =SUM(B39:D39) -> 89 | L39: Total Hrs/Yr | M39: =SUM(M32:M38) -> 8700 | N39: =SUM(N32:N38) -> 2622.5 | O39: =SUM(O32:O38) -> 6077.5
A40: CPA 1/2/3 | B40: =+B35*B37 -> 12 | C40: =+C35*C37 -> 8 | D40: =+D35*D37 -> 12.5 | E40: =SUM(B40:D40) -> 32.5
...

Sheet Special Project SOW & Est
A1: Hackbart & Companies | J1: Internal items/notes (DO NOT PRINT OR SHOW) | O1: Formula
A2: Date: 7/29/18 | B2: Prepared By: KC | J2: Last Updated: | K2: KC - 7/14/18
A4: Admin Items | J4: SOW TYPE: | K4: SPECIAL PROJECTS & CONSULTING
A5: Client Info
A6: Kevin Hackbart
A8: Projects Included | J8: General Hourly Bill & Cost Rates
A9: Description | B9: Budgeted Hours | C9: Budgeted Cost | D9: Budget or Related Notes | J9: Code | K9: Rate | L9: Description | M9: Internal Position Title | N9: Internal Cost Rate
A10: Mybeck Accounting | B10: =SUMIF($A$27:$A$39,A10,'Special Project SOW & Est'!$G$27:$G$39) -> 16 | C10: =SUMIF($A$27:$A$39,A10,'Special Project SOW & Est'!$H$27:$H$39) -> 1060 | J10: Admin | K10: 40 | L10: Admin | M10: Admin | N10: 16
A11: 2017 Mybeck Tax Returns -Fed/State | B11: =SUMIF($A$27:$A$39,A11,'Special Project SOW & Est'!$G$27:$G$39) -> 4 | C11: =SUMIF($A$27:$A$39,A11,'Special Project SOW & Est'!$H$27:$H$39) -> 484 | J11: BK | K11: 45 | L11: Bookkeeper | M11: Bookkeeper | N11: 18
A12: 10/10 Accounting | B12: =SUMIF($A$27:$A$39,A12,'Special Project SOW & Est'!$G$27:$G$39) -> 16 | C12: =SUMIF($A$27:$A$39,A12,'Special Project SOW & Est'!$H$27:$H$39) -> 1060 | J12: BK2 | K12: 65 | L12: Accountant | M12: Accountant | N12: 20
A13: 2017 10/10 Tax Returns - Fed/State | B13: =SUMIF($A$27:$A$39,A13,'Special Project SOW & Est'!$G$27:$G$39) -> 4 | C13: =SUMIF($A$27:$A$39,A13,'Special Project SOW & Est'!$H$27:$H$39) -> 484 | J13: Acct | K13: 70 | L13: Accounting Ptr | M13: Accounting Ptr | N13: 0 | O13: N/A - Captured in Admin
A14: Hackbart Personal Return | B14: =SUMIF($A$27:$A$39,A14,'Special Project SOW & Est'!$G$27:$G$39) -> 3 | C14: =SUMIF($A$27:$A$39,A14,'Special Project SOW & Est'!$H$27:$H$39) -> 363 | J14: CPA1 | K14: 121 | L14: Tax Preparer | M14: Tax Preparer | N14: 25
A15: Other | B15: =SUMIF($A$27:$A$39,A15,'Special Project SOW & Est'!$G$27:$G$39) -> 0 | C15: =SUMIF($A$27:$A$39,A15,'Special Project SOW & Est'!$H$27:$H$39) -> 0 | J15: CPA2 | K15: 135 | L15: Tax Reviewer | M15: Tax Reviewer | N15: 30
A16: Other | B16: =SUMIF($A$27:$A$39,A16,'Special Project SOW & Est'!$G$27:$G$39) -> 0 | C16: =SUMIF($A$27:$A$39,A16,'Special Project SOW & Est'!$H$27:$H$39) -> 0 | J16: CPA3 | K16: 150 | L16: Tax Partner | M16: Tax Partner | N16: 0 | O16: N/A - Captured in Admin
A17: Total Budgeted Hrs/Cost | B17: =SUM(B10:B16) -> 43 | C17: =SUM(C10:C16) -> 3451
A18: Discount | B18: 0.15 | C18: =+C17*-B18 -> -517.65 | D18: Former MO Client Discount
A19: Net Fee | C19: =SUM(C17:C18) -> 2933.35 | J19: Realized Hourly Rate (After Discount if Any)
A20: Total Fee Rounded | C20: 3000 | D20: Rounded | J20: Code | K20: Total Hrs | L20: % of Total Hrs | M20: Raw Fee | N20: % of Fee | O20: Net Fee | P20: Act Hrly Rate | Q20: Dept
J21: Admin | K21: =(SUMIF($F$27:$F$40,J21,$G$27:$G$40)) -> 0 | L21: =+K21/$K$28 -> 0 | M21: =+K21*K10 -> 0 | N21: =+M21/$M$28 -> 0 | O21: =$C$19*N21 -> 0 | P21: =IF(K21>0,+O21/K21,0) -> 0 | Q21: Admin
C22: =+C20*D22 -> 1500 | D22: 0.5 | E22: Amount Due With Engagement Signing | J22: BK | K22: =(SUMIF($F$27:$F$40,J22,$G$27:$G$40)) -> 0 | L22: =+K22/$K$28 -> 0 | M22: =+K22*K11 -> 0 | N22: =+M22/$M$28 -> 0 | O22: =$C$19*N22 -> 0 | P22: =IF(K22>0,+O22/K22,0) -> 0 | Q22: Acct
C23: =+C20-C22 -> 1500 | E23: *Balance Due Upon Completion | J23: BK2 | K23: =(SUMIF($F$27:$F$40,J23,$G$27:$G$40)) -> 24 | L23: =+K23/$K$28 -> 0.55813953 | M23: =+K23*K12 -> 1560 | N23: =+M23/$M$28 -> 0.45204289 | O23: =$C$19*N23 -> 1326 | P23: =IF(K23>0,+O23/K23,0) -> 55.25 | Q23: Acct
J24: Acct | K24: =(SUMIF($F$27:$F$40,J24,$G$27:$G$40)) -> 8 | L24: =+K24/$K$28 -> 0.18604651 | M24: =+K24*K13 -> 560 | N24: =+M24/$M$28 -> 0.16227181 | O24: =$C$19*N24 -> 476 | P24: =IF(K24>0,+O24/K24,0) -> 59.5 | Q24: Acct
A25: Time and Cost Budget Details | J25: CPA1 | K25: =(SUMIF($F$27:$F$40,J25,$G$27:$G$40)) -> 11 | L25: =+K25/$K$28 -> 0.25581395 | M25: =+K25*K14 -> 1331 | N25: =+M25/$M$28 -> 0.38568531 | O25: =$C$19*N25 -> 1131.35 | P25: =IF(K25>0,+O25/K25,0) -> 102.85 | Q25: Tax
A26: Project | B26: Task Details | F26: Level | G26: Budgeted Hrs | H26: Cost | J26: CPA2 | K26: =(SUMIF($F$27:$F$40,J26,$G$27:$G$40)) -> 0 | L26: =+K26/$K$28 -> 0 | M26: =+K26*K15 -> 0 | N26: =+M26/$M$28 -> 0 | O26: =$C$19*N26 -> 0 | P26: =IF(K26>0,+O26/K26,0) -> 0 | Q26: Tax
A27: Mybeck Accounting | B27: Accounting & Bookkeeping - Basic Prep | F27: BK2 | G27: 12 | H27: =IF(F27="Admin",$K$10*G27,IF(F27="BK",$K$11*G27,IF(F27="BK2",$K$12*G27,IF(F27="Acct",$K$13*G27,IF(F27="CPA1",$K$14*G27,IF(F27="CPA2",$K$15*G27,IF(F27="CPA3",$K$16*G27,""))))))) -> 780 | J27: CPA3 | K27: =(SUMIF($F$27:$F$40,J27,$G$27:$G$40)) -> 0 | L27: =+K27/$K$28 -> 0 | M27: =+K27*K16 -> 0 | N27: =+M27/$M$28 -> 0 | O27: =$C$19*N27 -> 0 | P27: =IF(K27>0,+O27/K27,0) -> 0 | Q27: Tax
A28: Mybeck Accounting | B28: Accounting & Bookkeeping - Review | F28: Acct | G28: 4 | H28: =IF(F28="Admin",$K$10*G28,IF(F28="BK",$K$11*G28,IF(F28="BK2",$K$12*G28,IF(F28="Acct",$K$13*G28,IF(F28="CPA1",$K$14*G28,IF(F28="CPA2",$K$15*G28,IF(F28="CPA3",$K$16*G28,""))))))) -> 280 | J28: Total Hrs/Yr | K28: =SUM(K21:K27) -> 43 | L28: =SUM(L21:L27) -> 1 | M28: =SUM(M21:M27) -> 3451 | N28: =SUM(N21:N27) -> 1 | O28: =SUM(O21:O27) -> 2933.35
A29: 10/10 Accounting | B29: Accounting & Bookkeeping - Basic Prep | F29: BK2 | G29: 12 | H29: =IF(F29="Admin",$K$10*G29,IF(F29="BK",$K$11*G29,IF(F29="BK2",$K$12*G29,IF(F29="Acct",$K$13*G29,IF(F29="CPA1",$K$14*G29,IF(F29="CPA2",$K$15*G29,IF(F29="CPA3",$K$16*G29,""))))))) -> 780
A30: 10/10 Accounting | B30: Accounting & Bookkeeping - Review | F30: Acct | G30: 4 | H30: =IF(F30="Admin",$K$10*G30,IF(F30="BK",$K$11*G30,IF(F30="BK2",$K$12*G30,IF(F30="Acct",$K$13*G30,IF(F30="CPA1",$K$14*G30,IF(F30="CPA2",$K$15*G30,IF(F30="CPA3",$K$16*G30,""))))))) -> 280
A31: 2017 Mybeck Tax Returns -Fed/State | B31: Prep & Review | F31: CPA1 | G31: 4 | H31: =IF(F31="Admin",$K$10*G31,IF(F31="BK",$K$11*G31,IF(F31="BK2",$K$12*G31,IF(F31="Acct",$K$13*G31,IF(F31="CPA1",$K$14*G31,IF(F31="CPA2",$K$15*G31,IF(F31="CPA3",$K$16*G31,""))))))) -> 484 | J31: Profitability & Gross/Net Profit %
A32: 2017 10/10 Tax Returns - Fed/State | B32: Prep & Review | F32: CPA1 | G32: 4 | H32: =IF(F32="Admin",$K$10*G32,IF(F32="BK",$K$11*G32,IF(F32="BK2",$K$12*G32,IF(F32="Acct",$K$13*G32,IF(F32="CPA1",$K$14*G32,IF(F32="CPA2",$K$15*G32,IF(F32="CPA3",$K$16*G32,""))))))) -> 484 | J32: Code | K32: Net Fee | L32: Tota Project Cost | M32: Project Profitability | N32: Gross Profit % | O32: Est G&A Exp % | P32: Take Home % | Q32: Dept
A33: Hackbart Personal Return | B33: Prep & Review | F33: CPA1 | G33: 3 | H33: =IF(F33="Admin",$K$10*G33,IF(F33="BK",$K$11*G33,IF(F33="BK2",$K$12*G33,IF(F33="Acct",$K$13*G33,IF(F33="CPA1",$K$14*G33,IF(F33="CPA2",$K$15*G33,IF(F33="CPA3",$K$16*G33,""))))))) -> 363 | J33: Admin | K33: =+O21 -> 0 | L33: =+K21*N10 -> 0 | M33: =+K33-L33 -> 0 | N33: =IF(M33>0,M33/K33,"-") -> - | O33: 0.38 | P33: =IF(M33>0,N33-O33,"-") -> - | Q33: Admin
A34: Other | H34: =IF(F34="Admin",$K$10*G34,IF(F34="BK",$K$11*G34,IF(F34="BK2",$K$12*G34,IF(F34="Acct",$K$13*G34,IF(F34="CPA1",$K$14*G34,IF(F34="CPA2",$K$15*G34,IF(F34="CPA3",$K$16*G34,""))))))) | J34: BK | K34: =+O22 -> 0 | L34: =+K22*N11 -> 0 | M34: =+K34-L34 -> 0 | N34: =IF(M34>0,M34/K34,"-") -> - | O34: 0.38 | P34: =IF(M34>0,N34-O34,"-") -> - | Q34: Acct
A35: Other | H35: =IF(F35="Admin",$K$10*G35,IF(F35="BK",$K$11*G35,IF(F35="BK2",$K$12*G35,IF(F35="Acct",$K$13*G35,IF(F35="CPA1",$K$14*G35,IF(F35="CPA2",$K$15*G35,IF(F35="CPA3",$K$16*G35,""))))))) | J35: BK2 | K35: =+O23 -> 1326 | L35: =+K23*N12 -> 480 | M35: =+K35-L35 -> 846 | N35: =IF(M35>0,M35/K35,"-") -> 0.63800905 | O35: 0.38 | P35: =IF(M35>0,N35-O35,"-") -> 0.25800905 | Q35: Acct
A36: Other | H36: =IF(F36="Admin",$K$10*G36,IF(F36="BK",$K$11*G36,IF(F36="BK2",$K$12*G36,IF(F36="Acct",$K$13*G36,IF(F36="CPA1",$K$14*G36,IF(F36="CPA2",$K$15*G36,IF(F36="CPA3",$K$16*G36,""))))))) | J36: Acct | K36: =+O24 -> 476 | L36: =+K24*N13 -> 0 | M36: =+K36-L36 -> 476 | N36: =IF(M36>0,M36/K36,"-") -> 1 | O36: 0.38 | P36: =IF(M36>0,N36-O36,"-") -> 0.62 | Q36: Acct
A37: Other | H37: =IF(F37="Admin",$K$10*G37,IF(F37="BK",$K$11*G37,IF(F37="BK2",$K$12*G37,IF(F37="Acct",$K$13*G37,IF(F37="CPA1",$K$14*G37,IF(F37="CPA2",$K$15*G37,IF(F37="CPA3",$K$16*G37,""))))))) | J37: CPA1 | K37: =+O25 -> 1131.35 | L37: =+K25*N14 -> 275 | M37: =+K37-L37 -> 856.35 | N37: =IF(M37>0,M37/K37,"-") -> 0.75692756 | O37: 0.38 | P37: =IF(M37>0,N37-O37,"-") -> 0.37692756 | Q37: Tax
A38: Other | H38: =IF(F38="Admin",$K$10*G38,IF(F38="BK",$K$11*G38,IF(F38="BK2",$K$12*G38,IF(F38="Acct",$K$13*G38,IF(F38="CPA1",$K$14*G38,IF(F38="CPA2",$K$15*G38,IF(F38="CPA3",$K$16*G38,""))))))) | J38: CPA2 | K38: =+O26 -> 0 | L38: =+K26*N15 -> 0 | M38: =+K38-L38 -> 0 | N38: =IF(M38>0,M38/K38,"-") -> - | O38: 0.38 | P38: =IF(M38>0,N38-O38,"-") -> - | Q38: Tax
A39: Other | H39: =IF(F39="Admin",$K$10*G39,IF(F39="BK",$K$11*G39,IF(F39="BK2",$K$12*G39,IF(F39="Acct",$K$13*G39,IF(F39="CPA1",$K$14*G39,IF(F39="CPA2",$K$15*G39,IF(F39="CPA3",$K$16*G39,""))))))) | J39: CPA3 | K39: =+O27 -> 0 | L39: =+K27*N16 -> 0 | M39: =+K39-L39 -> 0 | N39: =IF(M39>0,M39/K39,"-") -> - | O39: 0.38 | P39: =IF(M39>0,N39-O39,"-") -> - | Q39: Tax
F40: Totals | G40: =SUM(G27:G39) -> 43 | H40: =SUM(H27:H39) -> 3451 | J40: Total Hrs/Yr | K40: =SUM(K33:K39) -> 2933.35 | L40: =SUM(L33:L39) -> 755 | M40: =SUM(M33:M39) -> 2178.35
J42: Overall %
J46: Desired Goal & Break Even
...

Sheet Tax Returns & Consult SOW & Est
A1: Bsuiness Name/Client Name | J1: Internal items/notes (DO NOT PRINT OR SHOW) | O1: Formula
A2: Date: | B2: Prepared By: | J2: Last Updated: | K2: KC - 7/14/18
A4: Admin Items | J4: SOW TYPE: | K4: TAX RETURNS ONLY
A5: Client Info
A6: Individual's Name | J6: General Hourly Bill & Cost Rates
J7: Code | K7: Rate | L7: Description | M7: Internal Position Title | N7: Internal Cost Rate
A8: Tax Returns | B8: Fee Range | J8: Admin | K8: 40 | L8: Admin | M8: Admin | N8: 16
A9: Description | B9: Low | C9: High | D9: Budget or Related Notes | J9: BK | K9: 45 | L9: Bookkeeper | M9: Bookkeeper | N9: 18
A10: 1040 EZ | B10: =IF(A10="Other","-",_xlfn.IFS(A10=A55,H55,A10=A56,H56,A10=A57,H57,A10=A58,H58,A10=A59,H59,A10=A60,H60,A10=A61,H61,A10=A62,H62,A10=A63,H63,A10=A64,H64)) -> #N/A | C10: =VLOOKUP($A10,$J:$M,4,FALSE) -> 300 | J10: BK2 | K10: 65 | L10: Accountant | M10: Accountant | N10: 20
A11: 1040 Sched C - Complex | B11: =IF(A11="Other","-",_xlfn.IFS(A11=A55,H55,A11=A56,H56,A11=A57,H57,A11=A58,H58,A11=A59,H59,A11=A60,H60,A11=A61,H61,A11=A62,H62,A11=A63,H63,A11=A64,H64)) -> 800 | C11: =IF(A11="Other","-",_xlfn.IFS(A11=A55,H55,A11=A56,H56,A11=A57,H57,A11=A58,H58,A11=A59,H59,A11=A60,H60,A11=A61,H61,A11=A62,H62,A11=A63,H63,A11=A64,H64)+100) -> 900 | J11: Acct | K11: 70 | L11: Accounting Ptr | M11: Accounting Ptr | N11: 0 | O11: N/A - Captured in Admin
A12: Other | B12: =SUMIF($A$55:$A$67,#REF!,'Tax Returns & Consult SOW & Est'!$H$55:$H$67) -> 0 | C12: =SUMIF($A$55:$A$67,A12,'Tax Returns & Consult SOW & Est'!$H$55:$H$67) -> 0 | J12: CPA1 | K12: 150 | L12: Tax Preparer | M12: Tax Preparer | N12: 25
A13: Other | B13: =SUMIF($A$55:$A$67,#REF!,'Tax Returns & Consult SOW & Est'!$H$55:$H$67) -> 0 | C13: =SUMIF($A$55:$A$67,A13,'Tax Returns & Consult SOW & Est'!$H$55:$H$67) -> 0 | J13: CPA2 | K13: 160 | L13: Tax Reviewer | M13: Tax Reviewer | N13: 30
A14: Other | B14: =SUMIF($A$55:$A$67,#REF!,'Tax Returns & Consult SOW & Est'!$H$55:$H$67) -> 0 | C14: =SUMIF($A$55:$A$67,A14,'Tax Returns & Consult SOW & Est'!$H$55:$H$67) -> 0 | J14: CPA3 | K14: 175 | L14: Tax Partner | M14: Tax Partner | N14: 0 | O14: N/A - Captured in Admin
A15: Other | B15: =SUMIF($A$55:$A$67,#REF!,'Tax Returns & Consult SOW & Est'!$H$55:$H$67) -> 0 | C15: =SUMIF($A$55:$A$67,A15,'Tax Returns & Consult SOW & Est'!$H$55:$H$67) -> 0
A16: Other | B16: =SUMIF($A$55:$A$67,#REF!,'Tax Returns & Consult SOW & Est'!$H$55:$H$67) -> 0 | C16: =SUMIF($A$55:$A$67,A16,'Tax Returns & Consult SOW & Est'!$H$55:$H$67) -> 0
A17: Total Est Fee Range | B17: =SUM(B10:B16) -> #N/A | C17: =SUM(C10:C16) -> 1200 | J17: General Tax Return Pricing
A18: Discount | B18: 0 | C18: =+C17*-B18 -> 0 | J18: Code | K18: Rate Type | L18: Low | M18: High | N18: Est CPA Hrs | O18: Internal Position Title | P18: Internal Cost Rate | R18: Description
A19: Net Fee | B19: =SUM(B17:B18) -> #N/A | C19: =SUM(C17:C18) -> 1200 | J19: 1040 EZ | K19: Fixed | L19: 250 | M19: 300 | N19: 1 | P19: 16 | R19: 1040 EZ Form
J20: 1040 Basic | K20: Fixed | L20: 300 | M20: 400 | N20: 2 | P20: 18 | R20: 1040 with itemization, no sched C or E
A21: Additional Tax Related Projects or Consulting | J21: 1040 Mid-level | K21: Fixed | L21: 400 | M21: 500 | N21: 4 | P21: 20 | R21: Accountant
A22: Description | B22: Budgeted Hours | C22: Budgeted Cost | D22: Budget or Related Notes | J22: 1040 Complex | K22: Hourly | P22: 0 | Q22: N/A - Captured in Admin | R22: Accounting Ptr
A23: Other | B23: =SUMIF($A$55:$A$67,A23,'Tax Returns & Consult SOW & Est'!$G$55:$G$67) -> 0 | C23: =SUMIF($A$55:$A$67,A23,'Tax Returns & Consult SOW & Est'!$H$55:$H$67) -> 0 | J23: 1040 Sched C - Basic | K23: Fixed | L23: 99 | M23: 199 | P23: 25 | R23: Tax Preparer
A24: Other | B24: =SUMIF($A$55:$A$67,A24,'Tax Returns & Consult SOW & Est'!$G$55:$G$67) -> 0 | C24: =SUMIF($A$55:$A$67,A24,'Tax Returns & Consult SOW & Est'!$H$55:$H$67) -> 0 | J24: 1040 Sched C - Mid Range | K24: Fixed | L24: 200 | M24: 299 | P24: 30 | R24: Tax Reviewer
A25: Other | B25: =SUMIF($A$55:$A$67,A25,'Tax Returns & Consult SOW & Est'!$G$55:$G$67) -> 0 | C25: =SUMIF($A$55:$A$67,A25,'Tax Returns & Consult SOW & Est'!$H$55:$H$67) -> 0 | J25: 1040 Sched C - Complex | K25: Hourly | P25: 0 | Q25: N/A - Captured in Admin
A26: Other | B26: =SUMIF($A$55:$A$67,A26,'Tax Returns & Consult SOW & Est'!$G$55:$G$67) -> 0 | C26: =SUMIF($A$55:$A$67,A26,'Tax Returns & Consult SOW & Est'!$H$55:$H$67) -> 0 | J26: 1040 Sched E | K26: Fixed
A27: Total Budgeted Hrs/Cost | B27: =SUM(B23:B26) -> 0 | C27: =SUM(C23:C26) -> 0 | J27: 1040 Misc | K27: Hourly
A28: Discount | B28: 0 | C28: =+C27*-B28 -> 0
A29: Net Fee | C29: =SUM(C27:C28) -> 0 | J29: 1120 EZ
J30: 1120 Basic
J31: 1120 Mid-level
J32: 1120 Complex | K32: Hourly
A33: Time and Cost Budget Details | J33: 1120 Misc | K33: Hourly
A34: Tax Consulting or Related | B34: Task Details | F34: Level | G34: Budgeted Hrs | H34: Cost
A35: Accounting Cleanup & Related | F35: BK2 | G35: 6 | H35: =IF(F35="Admin",$L$19*G35,IF(F35="BK",$L$20*G35,IF(F35="BK2",$L$21*G35,IF(F35="Acct",$L$22*G35,IF(F35="CPA1",$L$23*G35,IF(F35="CPA2",$L$24*G35,IF(F35="CPA3",$L$25*G35,""))))))) -> 2400 | J35: 1120S EZ
A36: Accounting Cleanup & Related | F36: Acct | G36: 2 | H36: =IF(F36="Admin",$L$19*G36,IF(F36="BK",$L$20*G36,IF(F36="BK2",$L$21*G36,IF(F36="Acct",$L$22*G36,IF(F36="CPA1",$L$23*G36,IF(F36="CPA2",$L$24*G36,IF(F36="CPA3",$L$25*G36,""))))))) -> 0 | J36: 1120S Basic
A37: Amended Tax Returns 15-16 | F37: CPA2 | G37: 3 | H37: =IF(F37="Admin",$L$19*G37,IF(F37="BK",$L$20*G37,IF(F37="BK2",$L$21*G37,IF(F37="Acct",$L$22*G37,IF(F37="CPA1",$L$23*G37,IF(F37="CPA2",$L$24*G37,IF(F37="CPA3",$L$25*G37,""))))))) -> 600 | J37: 1120S Mid-level
A38: 2017 S Corp | F38: CPA2 | G38: 3 | H38: =IF(F38="Admin",$L$19*G38,IF(F38="BK",$L$20*G38,IF(F38="BK2",$L$21*G38,IF(F38="Acct",$L$22*G38,IF(F38="CPA1",$L$23*G38,IF(F38="CPA2",$L$24*G38,IF(F38="CPA3",$L$25*G38,""))))))) -> 600 | J38: 1120S Complex | K38: Hourly
A39: 2017 1040 | F39: CPA1 | G39: 3 | H39: =IF(F39="Admin",$L$19*G39,IF(F39="BK",$L$20*G39,IF(F39="BK2",$L$21*G39,IF(F39="Acct",$L$22*G39,IF(F39="CPA1",$L$23*G39,IF(F39="CPA2",$L$24*G39,IF(F39="CPA3",$L$25*G39,""))))))) -> 297 | J39: 1120S Misc | K39: Hourly
A40: Other | H40: =IF(F40="Admin",$L$19*G40,IF(F40="BK",$L$20*G40,IF(F40="BK2",$L$21*G40,IF(F40="Acct",$L$22*G40,IF(F40="CPA1",$L$23*G40,IF(F40="CPA2",$L$24*G40,IF(F40="CPA3",$L$25*G40,"")))))))
A41: Other | H41: =IF(F41="Admin",$L$19*G41,IF(F41="BK",$L$20*G41,IF(F41="BK2",$L$21*G41,IF(F41="Acct",$L$22*G41,IF(F41="CPA1",$L$23*G41,IF(F41="CPA2",$L$24*G41,IF(F41="CPA3",$L$25*G41,"")))))))
...
